Workbook

Sheet README
A1: India EV Charging Infrastructure Intelligence
A2: Data-driven analysis of public charging coverage, station density, and demand-supply mismatch across Indian states
A5: SHEETS IN THIS WORKBOOK
A6: 1. README — this page
A7: 2. OCM_Raw_Data — 1,179 geolocated public charging sites in India, sourced from OpenChargeMap (OCM) via the Open Charge Map API, filtered from a 242,417-site global dataset
A8: 3. State_Summary — station counts, ports, avg power, fast-DC share by state (computed from OCM raw data)
A9: 4. Official_vs_Crowdsourced — official Ministry of Power/PIB station counts benchmarked against OCM's crowdsourced coverage, by state
A10: 5. Demand_Supply_Gap — EV sales volumes vs charging stations, by state, with a stations-per-vehicle stress metric
A11: 6. Recommendations — expansion priority scoring by state
A13: DATA SOURCES (all real, publicly available, cited)
A14: - OpenChargeMap.org / Open Charge Map API (CC BY-SA 4.0) — geolocated station data, accessed via github.com/tarekmasryo/global-ev-infra-dataset
A15: - Press Information Bureau, Govt of India, Ministry of Heavy Industries, 08-Aug-2025 (PRID 2154127) — official national + top-7-state EVCS counts
... A25: - EV sales figures are only available for the 3 states with recent public reporting (Karnataka, Maharashtra, Uttar Pradesh) at the time of writing — this workbook does NOT fabricate numbers for states without a citable source. Blank cells are blank on purpose.

Sheet OCM_Raw_Data
A1: id | B1: name | C1: city | D1: state | E1: country_code | F1: latitude | G1: longitude | H1: ports | I1: power_kw | J1: power_class | K1: is_fast_dc
A2: 460636 | B2: Hotel Kantara Dine | C2: Solur | D2: Karnataka | E2: IN | F2: 13.064574 | G2: 77.257125 | H2: 1 | I2: 30 | J2: AC_HIGH_(22-49kW) | K2: =FALSE() -> FALSE
A3: 460478 | B3: Burger King | C3: Udayapura | D3: Karnataka | E3: IN | F3: 12.960134 | G3: 76.330239 | H3: 1 | I3: 120 | J3: DC_FAST_(50-149kW) | K3: =TRUE() -> TRUE
A4: 460205 | B4: Konnagar | C4: Kolkata | D4: West Bengal | E4: IN | F4: 21.651444 | G4: 87.6514 | H4: 1 | J4: UNKNOWN | K4: =FALSE() -> FALSE
A5: 458918 | B5: Tata.ev Luxon Motors - Tata Power | C5: Edappally | D5: Kerala | E5: IN | F5: 10.011485 | G5: 76.311387 | H5: 2 | I5: 60 | J5: DC_FAST_(50-149kW) | K5: =TRUE() -> TRUE
A6: 458917 | B6: TML Sree Gokulam Motors - Tata Power | C6: Edappally | D6: Kerala | E6: IN | F6: 10.039155 | G6: 76.315559 | H6: 1 | I6: 30 | J6: AC_HIGH_(22-49kW) | K6: =FALSE() -> FALSE
A7: 458916 | B7: Tata.ev Gokulam Motors - Tata Power | C7: Choornikkara | D7: Kerala | E7: IN | F7: 10.081303 | G7: 76.339462 | H7: 1 | I7: 60 | J7: DC_FAST_(50-149kW) | K7: =TRUE() -> TRUE
A8: 458915 | B8: Taj Cochin Internation Airport Hotel - Tata Power | C8: Nedumbassery | D8: Kerala | E8: IN | F8: 10.159995 | G8: 76.390154 | H8: 1 | I8: 30 | J8: AC_HIGH_(22-49kW) | K8: =FALSE() -> FALSE
A9: 458914 | B9: SAJ Earth Resort - Tata Power | C9: Nedumbassery | D9: Kerala | E9: IN | F9: 10.162224 | G9: 76.384653 | H9: 1 | I9: 30 | J9: AC_HIGH_(22-49kW) | K9: =FALSE() -> FALSE
A10: 458913 | B10: Luxon Motors - Tata Power | C10: Kariyad | D10: Kerala | E10: IN | F10: 10.162042 | G10: 76.367356 | H10: 1 | I10: 30 | J10: AC_HIGH_(22-49kW) | K10: =FALSE() -> FALSE
A11: 458912 | B11: Sree Gokulam Motors - Tata Power | C11: Angamaly | D11: Kerala | E11: IN | F11: 10.22106 | G11: 76.376752 | H11: 1 | I11: 30 | J11: AC_HIGH_(22-49kW) | K11: =FALSE() -> FALSE
A12: 458911 | B12: Centro Mall Charging Station - Tata Power | C12: Kodungallur | D12: Kerala | E12: IN | F12: 10.232489 | G12: 76.19594 | H12: 1 | I12: 30 | J12: AC_HIGH_(22-49kW) | K12: =FALSE() -> FALSE
A13: 458910 | B13: IOCL Thiruvonam Fuels - Tata Power | C13: Palakkad | D13: Kerala | E13: IN | F13: 10.769831 | G13: 76.668097 | H13: 2 | I13: 30 | J13: AC_HIGH_(22-49kW) | K13: =FALSE() -> FALSE
A14: 458909 | B14: KVR Automotive - Tata Power | C14: Koppam | D14: Kerala | E14: IN | F14: 10.782258 | G14: 76.658245 | H14: 1 | I14: 30 | J14: AC_HIGH_(22-49kW) | K14: =FALSE() -> FALSE
A15: 458908 | B15: Gokulam Residency - Tata Power | C15: Amballur | D15: Kerala | E15: IN | F15: 10.436187 | G15: 76.265206 | H15: 1 | I15: 25 | J15: AC_HIGH_(22-49kW) | K15: =FALSE() -> FALSE
A16: 458907 | B16: Tata.ev Hyson Motors - Tata Power | C16: Thrissur | D16: Kerala | E16: IN | F16: 10.496728 | G16: 76.258361 | H16: 2 | I16: 60 | J16: DC_FAST_(50-149kW) | K16: =TRUE() -> TRUE
A17: 458906 | B17: PCK Centenary | C17: Thrissur | D17: Kerala | E17: IN | F17: 10.52294 | G17: 76.206248 | H17: 1 | I17: 30 | J17: AC_HIGH_(22-49kW) | K17: =FALSE() -> FALSE
A18: 458905 | B18: TML Hyson Motors - Tata Power | C18: Thrissur | D18: Kerala | E18: IN | F18: 10.540423 | G18: 76.189678 | H18: 2 | I18: 25 | J18: AC_HIGH_(22-49kW) | K18: =FALSE() -> FALSE
A19: 458904 | B19: Hotel Gokulam Sabari - Tata Power | C19: Guruvayur | D19: Kerala | E19: IN | F19: 10.596357 | G19: 76.042934 | H19: 2 | I19: 25 | J19: AC_HIGH_(22-49kW) | K19: =FALSE() -> FALSE
A20: 314018 | B20: Shirdi | C20: Shirdi | D20: Maharashtra | E20: IN | F20: 19.757594 | G20: 74.476347 | H20: 1 | I20: 30 | J20: AC_HIGH_(22-49kW) | K20: =FALSE() -> FALSE
A21: 313995 | B21: InFour Wheel Care And Tyres - Tata Power | C21: Perinthalmanna | D21: Kerala | E21: IN | F21: 10.960238 | G21: 76.234679 | H21: 1 | I21: 25 | J21: AC_HIGH_(22-49kW) | K21: =FALSE() -> FALSE
A22: 313994 | B22: TML KVR Automotive - Tata Power | C22: Perinthalmanna | D22: Kerala | E22: IN | F22: 10.984503 | G22: 76.187847 | H22: 1 | I22: 30 | J22: AC_HIGH_(22-49kW) | K22: =FALSE() -> FALSE
A23: 313993 | B23: IOCL Sigma Enterprises Charging Station - Tata Power | C23: Valanchery | D23: Kerala | E23: IN | F23: 10.897914 | G23: 76.06101 | H23: 1 | I23: 30 | J23: AC_HIGH_(22-49kW) | K23: =FALSE() -> FALSE
A24: 313992 | B24: AAK Mall | C24: Tirur | D24: Kerala | E24: IN | F24: 10.918581 | G24: 75.917798 | H24: 1 | I24: 30 | J24: AC_HIGH_(22-49kW) | K24: =FALSE() -> FALSE
A25: 313991 | B25: Tata.ev Store Malappuram | C25: Malappuram | D25: Kerala | E25: IN | F25: 11.052515 | G25: 76.07764 | H25: 2 | I25: 60 | J25: DC_FAST_(50-149kW) | K25: =TRUE() -> TRUE
A26: 313990 | B26: A M Tyres Malappuram - Tata Power | C26: Malappuram | D26: Kerala | E26: IN | F26: 11.060403 | G26: 76.080844 | H26: 1 | I26: 30 | J26: AC_HIGH_(22-49kW) | K26: =FALSE() -> FALSE
A27: 313989 | B27: Hotel Gokulam Relax Park | C27: Manjeri | D27: Kerala | E27: IN | F27: 11.118906 | G27: 76.118474 | H27: 2 | I27: 25 | J27: AC_HIGH_(22-49kW) | K27: =FALSE() -> FALSE
A28: 313988 | B28: One Stop Automotive Cahrging Station - Tata Power | C28: Edavanna | D28: Kerala | E28: IN | F28: 11.204146 | G28: 76.136734 | H28: 2 | I28: 60 | J28: DC_FAST_(50-149kW) | K28: =TRUE() -> TRUE
A29: 313980 | B29: Moto Town Auto Hub - Tata Power | C29: Wandoor | D29: Kerala | E29: IN | F29: 11.22325 | G29: 76.216915 | H29: 1 | I29: 30 | J29: AC_HIGH_(22-49kW) | K29: =FALSE() -> FALSE
A30: 313979 | B30: IOCL Aaditya Petroleum Naduvath Charging Station - Tata Power | C30: Wandoor | D30: Kerala | E30: IN | F30: 11.211054 | G30: 76.224685 | H30: 1 | I30: 30 | J30: AC_HIGH_(22-49kW) | K30: =FALSE() -> FALSE
A31: 313978 | B31: Calicut Airport Charging Station - Tata Power | C31: Kondotty | D31: Kerala | E31: IN | F31: 11.140292 | G31: 75.948314 | H31: 2 | I31: 60 | J31: DC_FAST_(50-149kW) | K31: =TRUE() -> TRUE
A32: 313955 | B32: TML Marina Motors - Tata Power | C32: Kozhikode | D32: Kerala | E32: IN | F32: 11.216965 | G32: 75.857951 | H32: 2 | I32: 25 | J32: AC_HIGH_(22-49kW) | K32: =FALSE() -> FALSE
A33: 313954 | B33: Rotana Motors Meenchanda - Tata Power | C33: Meenchanda | D33: Kerala | E33: IN | F33: 11.213909 | G33: 75.802632 | H33: 1 | I33: 30 | J33: AC_HIGH_(22-49kW) | K33: =FALSE() -> FALSE
A34: 313953 | B34: IOCL Lakshmi Sales & Service - Tata Power | C34: Kozhikode | D34: Kerala | E34: IN | F34: 11.233627 | G34: 75.803239 | H34: 1 | I34: 30 | J34: AC_HIGH_(22-49kW) | K34: =FALSE() -> FALSE
A35: 313952 | B35: Gokulam Galleria Mall - Tata Power | C35: Kozhikode | D35: Kerala | E35: IN | F35: 11.258465 | G35: 75.792906 | H35: 5 | I35: 25 | J35: AC_HIGH_(22-49kW) | K35: =FALSE() -> FALSE
A36: 313951 | B36: Hotel Hyson Heritage - Tata Power | C36: Kozhikode | D36: Kerala | E36: IN | F36: 11.259214 | G36: 75.779335 | H36: 2 | I36: 25 | J36: AC_HIGH_(22-49kW) | K36: =FALSE() -> FALSE
A37: 313950 | B37: Taj The Gateway Hotel - Tata Power | C37: Kozhikode | D37: Kerala | E37: IN | F37: 11.25869 | G37: 75.773979 | H37: 2 | I37: 30 | J37: AC_HIGH_(22-49kW) | K37: =FALSE() -> FALSE
A38: 313947 | B38: IOCL Engapuzha Fuel - Tata Power | C38: Engapuzha | D38: Kerala | E38: IN | F38: 11.46505 | G38: 75.970175 | H38: 1 | I38: 25 | J38: AC_HIGH_(22-49kW) | K38: =FALSE() -> FALSE
A39: 313946 | B39: IOCl Balaji Petroleum - Tata Power | C39: Sulthan Bathery | D39: Kerala | E39: IN | F39: 11.660943 | G39: 76.240023 | H39: 1 | I39: 30 | J39: AC_HIGH_(22-49kW) | K39: =FALSE() -> FALSE
A40: 313945 | B40: Hotel Saugandhika Charging Station - Tata Power | C40: Meenangadi | D40: Kerala | E40: IN | F40: 11.659328 | G40: 76.207185 | H40: 2 | I40: 60 | J40: DC_FAST_(50-149kW) | K40: =TRUE() -> TRUE
...

Sheet State_Summary
A1: State | B1: OCM Sites (COUNTIFS) | C1: Total Ports (SUMIFS) | D1: Avg Power kW (AVERAGEIFS) | E1: Fast-DC Sites | F1: Fast-DC Share %
A2: Kerala | B2: =COUNTIFS(OCM_Raw_Data!$D$2:$D$1181,A2) -> 454 | C2: =SUMIFS(OCM_Raw_Data!$H$2:$H$1181,OCM_Raw_Data!$D$2:$D$1181,A2) -> 1001 | D2: =IFERROR(AVERAGEIFS(OCM_Raw_Data!$I$2:$I$1181,OCM_Raw_Data!$D$2:$D$1181,A2),0) -> 38.354185 | E2: =COUNTIFS(OCM_Raw_Data!$D$2:$D$1181,A2,OCM_Raw_Data!$K$2:$K$1181,TRUE()) -> 136 | F2: =E2/B2 -> 0.29955947
A3: Karnataka | B3: =COUNTIFS(OCM_Raw_Data!$D$2:$D$1181,A3) -> 362 | C3: =SUMIFS(OCM_Raw_Data!$H$2:$H$1181,OCM_Raw_Data!$D$2:$D$1181,A3) -> 524 | D3: =IFERROR(AVERAGEIFS(OCM_Raw_Data!$I$2:$I$1181,OCM_Raw_Data!$D$2:$D$1181,A3),0) -> 52.577072 | E3: =COUNTIFS(OCM_Raw_Data!$D$2:$D$1181,A3,OCM_Raw_Data!$K$2:$K$1181,TRUE()) -> 196 | F3: =E3/B3 -> 0.54143646
A4: Tamil Nadu | B4: =COUNTIFS(OCM_Raw_Data!$D$2:$D$1181,A4) -> 182 | C4: =SUMIFS(OCM_Raw_Data!$H$2:$H$1181,OCM_Raw_Data!$D$2:$D$1181,A4) -> 208 | D4: =IFERROR(AVERAGEIFS(OCM_Raw_Data!$I$2:$I$1181,OCM_Raw_Data!$D$2:$D$1181,A4),0) -> 41.572222 | E4: =COUNTIFS(OCM_Raw_Data!$D$2:$D$1181,A4,OCM_Raw_Data!$K$2:$K$1181,TRUE()) -> 59 | F4: =E4/B4 -> 0.32417582
A5: Rajasthan | B5: =COUNTIFS(OCM_Raw_Data!$D$2:$D$1181,A5) -> 34 | C5: =SUMIFS(OCM_Raw_Data!$H$2:$H$1181,OCM_Raw_Data!$D$2:$D$1181,A5) -> 65 | D5: =IFERROR(AVERAGEIFS(OCM_Raw_Data!$I$2:$I$1181,OCM_Raw_Data!$D$2:$D$1181,A5),0) -> 30.529412 | E5: =COUNTIFS(OCM_Raw_Data!$D$2:$D$1181,A5,OCM_Raw_Data!$K$2:$K$1181,TRUE()) -> 2 | F5: =E5/B5 -> 0.058823529
A6: Delhi | B6: =COUNTIFS(OCM_Raw_Data!$D$2:$D$1181,A6) -> 30 | C6: =SUMIFS(OCM_Raw_Data!$H$2:$H$1181,OCM_Raw_Data!$D$2:$D$1181,A6) -> 53 | D6: =IFERROR(AVERAGEIFS(OCM_Raw_Data!$I$2:$I$1181,OCM_Raw_Data!$D$2:$D$1181,A6),0) -> 31.333333 | E6: =COUNTIFS(OCM_Raw_Data!$D$2:$D$1181,A6,OCM_Raw_Data!$K$2:$K$1181,TRUE()) -> 8 | F6: =E6/B6 -> 0.26666667
A7: Haryana | B7: =COUNTIFS(OCM_Raw_Data!$D$2:$D$1181,A7) -> 27 | C7: =SUMIFS(OCM_Raw_Data!$H$2:$H$1181,OCM_Raw_Data!$D$2:$D$1181,A7) -> 59 | D7: =IFERROR(AVERAGEIFS(OCM_Raw_Data!$I$2:$I$1181,OCM_Raw_Data!$D$2:$D$1181,A7),0) -> 49.518519 | E7: =COUNTIFS(OCM_Raw_Data!$D$2:$D$1181,A7,OCM_Raw_Data!$K$2:$K$1181,TRUE()) -> 11 | F7: =E7/B7 -> 0.40740741
A8: Gujarat | B8: =COUNTIFS(OCM_Raw_Data!$D$2:$D$1181,A8) -> 23 | C8: =SUMIFS(OCM_Raw_Data!$H$2:$H$1181,OCM_Raw_Data!$D$2:$D$1181,A8) -> 35 | D8: =IFERROR(AVERAGEIFS(OCM_Raw_Data!$I$2:$I$1181,OCM_Raw_Data!$D$2:$D$1181,A8),0) -> 31.18 | E8: =COUNTIFS(OCM_Raw_Data!$D$2:$D$1181,A8,OCM_Raw_Data!$K$2:$K$1181,TRUE()) -> 3 | F8: =E8/B8 -> 0.13043478
A9: Uttar Pradesh | B9: =COUNTIFS(OCM_Raw_Data!$D$2:$D$1181,A9) -> 21 | C9: =SUMIFS(OCM_Raw_Data!$H$2:$H$1181,OCM_Raw_Data!$D$2:$D$1181,A9) -> 37 | D9: =IFERROR(AVERAGEIFS(OCM_Raw_Data!$I$2:$I$1181,OCM_Raw_Data!$D$2:$D$1181,A9),0) -> 52.425 | E9: =COUNTIFS(OCM_Raw_Data!$D$2:$D$1181,A9,OCM_Raw_Data!$K$2:$K$1181,TRUE()) -> 10 | F9: =E9/B9 -> 0.47619048
A10: Maharashtra | B10: =COUNTIFS(OCM_Raw_Data!$D$2:$D$1181,A10) -> 16 | C10: =SUMIFS(OCM_Raw_Data!$H$2:$H$1181,OCM_Raw_Data!$D$2:$D$1181,A10) -> 33 | D10: =IFERROR(AVERAGEIFS(OCM_Raw_Data!$I$2:$I$1181,OCM_Raw_Data!$D$2:$D$1181,A10),0) -> 58.071429 | E10: =COUNTIFS(OCM_Raw_Data!$D$2:$D$1181,A10,OCM_Raw_Data!$K$2:$K$1181,TRUE()) -> 10 | F10: =E10/B10 -> 0.625
A11: Telangana | B11: =COUNTIFS(OCM_Raw_Data!$D$2:$D$1181,A11) -> 7 | C11: =SUMIFS(OCM_Raw_Data!$H$2:$H$1181,OCM_Raw_Data!$D$2:$D$1181,A11) -> 8 | D11: =IFERROR(AVERAGEIFS(OCM_Raw_Data!$I$2:$I$1181,OCM_Raw_Data!$D$2:$D$1181,A11),0) -> 49.066667 | E11: =COUNTIFS(OCM_Raw_Data!$D$2:$D$1181,A11,OCM_Raw_Data!$K$2:$K$1181,TRUE()) -> 2 | F11: =E11/B11 -> 0.28571429
A12: Goa | B12: =COUNTIFS(OCM_Raw_Data!$D$2:$D$1181,A12) -> 6 | C12: =SUMIFS(OCM_Raw_Data!$H$2:$H$1181,OCM_Raw_Data!$D$2:$D$1181,A12) -> 6 | D12: =IFERROR(AVERAGEIFS(OCM_Raw_Data!$I$2:$I$1181,OCM_Raw_Data!$D$2:$D$1181,A12),0) -> 50 | E12: =COUNTIFS(OCM_Raw_Data!$D$2:$D$1181,A12,OCM_Raw_Data!$K$2:$K$1181,TRUE()) -> 4 | F12: =E12/B12 -> 0.66666667
A13: West Bengal | B13: =COUNTIFS(OCM_Raw_Data!$D$2:$D$1181,A13) -> 6 | C13: =SUMIFS(OCM_Raw_Data!$H$2:$H$1181,OCM_Raw_Data!$D$2:$D$1181,A13) -> 6 | D13: =IFERROR(AVERAGEIFS(OCM_Raw_Data!$I$2:$I$1181,OCM_Raw_Data!$D$2:$D$1181,A13),0) -> 42 | E13: =COUNTIFS(OCM_Raw_Data!$D$2:$D$1181,A13,OCM_Raw_Data!$K$2:$K$1181,TRUE()) -> 2 | F13: =E13/B13 -> 0.33333333
A14: Andhra Pradesh | B14: =COUNTIFS(OCM_Raw_Data!$D$2:$D$1181,A14) -> 3 | C14: =SUMIFS(OCM_Raw_Data!$H$2:$H$1181,OCM_Raw_Data!$D$2:$D$1181,A14) -> 4 | D14: =IFERROR(AVERAGEIFS(OCM_Raw_Data!$I$2:$I$1181,OCM_Raw_Data!$D$2:$D$1181,A14),0) -> 70 | E14: =COUNTIFS(OCM_Raw_Data!$D$2:$D$1181,A14,OCM_Raw_Data!$K$2:$K$1181,TRUE()) -> 1 | F14: =E14/B14 -> 0.33333333
A15: TOTAL / NATIONAL AVG | B15: =SUM(B2:B14) -> 1171 | C15: =SUM(C2:C14) -> 2039 | D15: =AVERAGE(D2:D14) -> 45.894449 | E15: =SUM(E2:E14) -> 444 | F15: =E15/B15 -> 0.37916311
A17: Note: this sheet reflects OCM (crowdsourced) coverage only — see Official_vs_Crowdsourced for real installed-base comparison.

Sheet Official_vs_Crowdsourced
A1: State | B1: Official PIB EVCS (as of 01-Aug-2025) | C1: OCM-Mapped Sites | D1: OCM Coverage % of Official | E1: Source
A2: Karnataka | B2: 6097 | C2: =COUNTIFS(OCM_Raw_Data!$D$2:$D$1181,A2) -> 362 | D2: =C2/B2 -> 0.059373462 | E2: Sec.3.1, PIB PRID 2154127 (via TeslaVolts Table 3.1)
A3: Maharashtra | B3: 4155 | C3: =COUNTIFS(OCM_Raw_Data!$D$2:$D$1181,A3) -> 16 | D3: =C3/B3 -> 0.0038507822 | E3: Sec.3.1, PIB PRID 2154127 (via TeslaVolts Table 3.1)
A4: Uttar Pradesh | B4: 2326 | C4: =COUNTIFS(OCM_Raw_Data!$D$2:$D$1181,A4) -> 21 | D4: =C4/B4 -> 0.0090283749 | E4: PIB PRID 2154127, Annexure A (direct, MoP)
A5: Delhi | B5: 1967 | C5: =COUNTIFS(OCM_Raw_Data!$D$2:$D$1181,A5) -> 30 | D5: =C5/B5 -> 0.015251652 | E5: Sec.3.1, PIB PRID 2154127 (via TeslaVolts Table 3.1)
A6: Tamil Nadu | B6: 1781 | C6: =COUNTIFS(OCM_Raw_Data!$D$2:$D$1181,A6) -> 182 | D6: =C6/B6 -> 0.10218978 | E6: Sec.3.1, PIB PRID 2154127 (via TeslaVolts Table 3.1)
A7: Rajasthan | B7: 1531 | C7: =COUNTIFS(OCM_Raw_Data!$D$2:$D$1181,A7) -> 34 | D7: =C7/B7 -> 0.022207707 | E7: Sec.3.1, PIB PRID 2154127 (via TeslaVolts Table 3.1)
A8: Kerala | B8: 1392 | C8: =COUNTIFS(OCM_Raw_Data!$D$2:$D$1181,A8) -> 454 | D8: =C8/B8 -> 0.32614943 | E8: Sec.3.1, PIB PRID 2154127 (via TeslaVolts Table 3.1)
A9: TOTAL (these 7 states) | B9: =SUM(B2:B8) -> 19249 | C9: =SUM(C2:C8) -> 1099 | D9: =C9/B9 -> 0.057093875
A11: National context (not state-summable):
A12: Official national public EVCS, 01-Aug-2025 (PIB PRID 2154127) | B12: 29277
A13: Total OCM-mapped India sites (this workbook, cleaned) | B13: =COUNTA(OCM_Raw_Data!A2:A1181) -> 1179
A14: Implied national OCM coverage % | B14: =B13/B12 -> 0.04027052
A16: Interpretation: yellow-filled cells are hardcoded official figures sourced from PIB — cite these for any real headline claim about India's charging network. OCM coverage % measures ONLY how discoverable a state's stations are on the crowdsourced OpenChargeMap platform, not infrastructure quality or adequacy.

Sheet Demand_Supply_Gap
A1: State | B1: Official EVCS (Aug-2025) | C1: EV Sales, CY2025 (units) | D1: Share of Natl EV Sales 2025 | E1: New EVs Sold per Station (2025) | F1: Stress Rank (1=worst)
A2: Uttar Pradesh | B2: 2326 | C2: 400000 | D2: 0.18 | E2: =C2/B2 -> 171.96905 | F2: =RANK(E2,$E$2:$E$4,0) -> 1
A3: Maharashtra | B3: 4155 | C3: 266000 | D3: 0.12 | E3: =C3/B3 -> 64.019254 | F3: =RANK(E3,$E$2:$E$4,0) -> 2
A4: Karnataka | B4: 6097 | C4: 173000 | E4: =C4/B4 -> 28.37461 | F4: =RANK(E4,$E$2:$E$4,0) -> 3
A7: Sources
A8: Uttar Pradesh: PIB PRID2154127 (stations); Navionyx/Vahan-derived, 2025 (sales, 18% natl share)
A9: Maharashtra: PIB PRID2154127 (stations); Navionyx/Vahan-derived, 2025 (sales, 12% natl share)
A10: Karnataka: PIB PRID2154127 (stations); Deccan Herald, FY24-25 EV sales (2W+3W+4W), citing MoRTH/RTO data
A13: National context
A14: Cumulative EVs registered nationally, as of 08-Feb-2025 (e-Vahan / PIB PRID2101635) | B14: 5675000
A15: Public EVCS nationally, as of 01-Aug-2025 (PIB PRID2154127) | B15: 29277
A16: Implied national installed-base ratio (cumulative EVs per station — NOT an annual-flow metric, differs from cols above) | B16: =B14/B15 -> 193.83817
A18: Read this table as: how many NEW EVs were sold in 2025 for every EXISTING public station — a stress/pressure metric on the current network, not a literal 'cars per plug' figure (each EV doesn't need its own charger). Higher = more pressure on existing infrastructure.

Sheet Recommendations
A1: Strategic recommendations — where to prioritize new public charging investment
A3: 1. Uttar Pradesh is the single highest-pressure state in the network.
A4: UP sold 18% of India's 2025 EV volume (~4 lakh units, mostly e-2W/e-3W) but holds only 8% of the top-7 states' charging stations (2,326 of 29,277 nationally). At ~172 new EVs sold per existing station in 2025 alone, UP's stress ratio is roughly 6x Karnataka's (~28:1). Because UP's EV mix is dominated by two/three-wheelers that mostly charge at home or via battery swapping, this is less acute for range anxiety than the raw ratio implies — but it's still the state where new public DC/AC capacity should be added first for four-wheeler and fleet segments.
A6: 2. Karnataka's density masks a Bengaluru-only story.
A7: 6,097 stations sounds dominant, but public reporting (Deccan Herald, Aug 2025) puts the count much lower at city/state-department level (468 in one district-level count), and industry sources note utilization outside Bengaluru is thin. Don't read 'most stations' as 'most accessible' — recommend a district-level follow-up study before assuming Karnataka's infrastructure gap is closed.
A9: 3. Crowdsourced platforms (Google Maps/OSM-linked apps) undercount India's real network by ~96%.
A10: OCM shows 1,178 mapped stations against an official 29,277 — a coverage gap that matters directly for any GTM plan built on 'where do EV drivers currently look for chargers.' A charge-point operator or app relying on OCM/OSM data alone is working from a dataset that's missing the vast majority of real stations, mostly OMC-installed sites (IOCL alone operates 7,928) that haven't been crowd-mapped.
A12: 4. Fast-DC share is a Karnataka/Maharashtra/UP story, not a national one.
A13: In the OCM-mapped subset, fast-DC share is 54% in Karnataka and 63% in Maharashtra but under 6% in Rajasthan and 13% in Gujarat. If the goal is highway-corridor readiness (PM E-DRIVE's 50-corridor target), Rajasthan and Gujarat's AC-heavy networks are the weaker links despite reasonable total station counts.
A15: 5. Data quality is itself a finding.
A16: The raw crowdsourced dataset contained a 1,000,000 kW power rating on a single-port site (obvious data entry error) and 10+ garbled/misspelled state labels. Any pipeline consuming OCM data directly needs validation rules on power_kw (cap at physically plausible values, e.g. 400 kW) and a state-name canonicalization step before it's usable for reporting.
